{
  "task": "incident_triage",
  "input": "{\r\n  \"logs\": [\r\n    {\r\n      \"timestamp\": \"2025-01-15T10:30:00Z\",\r\n      \"level\": \"ERROR\",\r\n      \"message\": \"Database connection failed: timeout after 30 seconds\",\r\n      \"service\": \"auth-service\",\r\n      \"trace_id\": \"abc123\"\r\n    },\r\n    {\r\n      \"timestamp\": \"2025-01-15T10:31:00Z\",\r\n      \"level\": \"WARN\",\r\n      \"message\": \"Retrying database connection attempt 1/3\",\r\n      \"service\": \"auth-service\",\r\n      \"trace_id\": \"abc123\"\r\n    },\r\n    {\r\n      \"timestamp\": \"2025-01-15T10:32:00Z\",\r\n      \"level\": \"ERROR\",\r\n      \"message\": \"Database connection failed: timeout after 30 seconds\",\r\n      \"service\": \"auth-service\",\r\n      \"trace_id\": \"abc123\"\r\n    },\r\n    {\r\n      \"timestamp\": \"2025-01-15T10:35:00Z\",\r\n      \"level\": \"ERROR\",\r\n      \"message\": \"Service unavailable: all database connections exhausted\",\r\n      \"service\": \"auth-service\",\r\n      \"trace_id\": \"def456\"\r\n    }\r\n  ],\r\n  \"incident_id\": \"INC-2025-001\",\r\n  \"severity\": \"HIGH\",\r\n  \"affected_services\": [\"auth-service\", \"user-service\"],\r\n  \"reported_by\": \"oncall-eng\"\r\n}\r\n\r\n",
  "result": {
    "success": false,
    "error": "The OPENAI_API_KEY environment variable is missing or empty; either provide it, or instantiate the OpenAI client with an apiKey option, like new OpenAI({ apiKey: 'My API Key' }).",
    "provider": "unknown",
    "timestamp": "2025-08-17T06:31:02.137Z"
  },
  "timestamp": "2025-08-17T06:31:02.137Z",
  "runner": "runTask.ts"
}